Workbook

Sheet MLB Pitchers 2018-2023 TJ
A1: Player | B1: Age | C1: Team | D1: Position | E1: Throwing Hand | F1: Country | G1: Surgery Year | H1: Surgery Date | I1: Return Date | J1: Games - Before | K1: Games - After | L1: Games Started - Before | M1: Games Started - After | N1: Innings Pitched - Before | O1: Innings Pitched - After | P1: K-BB% - Before | Q1: K-BB% - After | R1: ERA - Before | S1: ERA - After | T1: FIP - Before | U1: FIP - After | V1: FgID | W1: Diff in ERA(- improvement) | X1: Diff in FIP(- improvement) | Y1: Diff in K-BB%(+ improvement) | Z1: Paired IP Weight | AA1: Weighted ERA Contribution | AB1: Weighted FIP Contribution | AC1: Weighted K-BB% Contribution
A2: Johan Oviedo | B2: 25 | C2: PIT | D2: P | E2: R | F2: Cuba | G2: 2023 | H2: 45261 | I2: 45873 | J2: 40 | K2: 10 | L2: 26 | M2: 9 | N2: 143 | O2: 44 | P2: 0.0794 | Q2: 0.1117 | R2: 4.3427 | S2: 4.0909 | T2: 4.676 | U2: 5.3592 | V2: 22487 | W2: =IF(AND(ISNUMBER(N2),ISNUMBER(O2),ISNUMBER(P2),ISNUMBER(Q2),ISNUMBER(R2),ISNUMBER(S2),ISNUMBER(T2),ISNUMBER(U2),N2>0,O2>0),S2-R2,"") -> -0.2518 | X2: =IF(AND(ISNUMBER(N2),ISNUMBER(O2),ISNUMBER(P2),ISNUMBER(Q2),ISNUMBER(R2),ISNUMBER(S2),ISNUMBER(T2),ISNUMBER(U2),N2>0,O2>0),U2-T2,"") -> 0.6832 | Y2: =IF(AND(ISNUMBER(N2),ISNUMBER(O2),ISNUMBER(P2),ISNUMBER(Q2),ISNUMBER(R2),ISNUMBER(S2),ISNUMBER(T2),ISNUMBER(U2),N2>0,O2>0),Q2-P2,"") -> 0.0323 | Z2: =IF(AND(ISNUMBER(N2),ISNUMBER(O2),ISNUMBER(P2),ISNUMBER(Q2),ISNUMBER(R2),ISNUMBER(S2),ISNUMBER(T2),ISNUMBER(U2),N2>0,O2>0),MIN((INT(N2)*3+ROUND(MOD(N2,1)*10,0))/3,(INT(O2)*3+ROUND(MOD(O2,1)*10,0))/3),"") -> 44 | AA2: =IF(ISNUMBER(Z2),W2*Z2,"") -> -11.0792 | AB2: =IF(ISNUMBER(Z2),X2*Z2,"") -> 30.0608 | AC2: =IF(ISNUMBER(Z2),Y2*Z2,"") -> 1.4212
A3: Felix Bautista | B3: 28 | C3: BAL | D3: P | E3: R | F3: Dominican | G3: 2023 | H3: 45208 | I3: 45745 | J3: 65 | K3: 37 | L3: 0 | M3: 0 | N3: 65.2 | O3: 36.1 | P3: 0.2569 | Q3: 0.1908 | R3: 2.1929 | S3: 3.2202 | T3: 2.91 | U3: 3.6328 | V3: 20666 | W3: =IF(AND(ISNUMBER(N3),ISNUMBER(O3),ISNUMBER(P3),ISNUMBER(Q3),ISNUMBER(R3),ISNUMBER(S3),ISNUMBER(T3),ISNUMBER(U3),N3>0,O3>0),S3-R3,"") -> 1.0273 | X3: =IF(AND(ISNUMBER(N3),ISNUMBER(O3),ISNUMBER(P3),ISNUMBER(Q3),ISNUMBER(R3),ISNUMBER(S3),ISNUMBER(T3),ISNUMBER(U3),N3>0,O3>0),U3-T3,"") -> 0.7228 | Y3: =IF(AND(ISNUMBER(N3),ISNUMBER(O3),ISNUMBER(P3),ISNUMBER(Q3),ISNUMBER(R3),ISNUMBER(S3),ISNUMBER(T3),ISNUMBER(U3),N3>0,O3>0),Q3-P3,"") -> -0.0661 | Z3: =IF(AND(ISNUMBER(N3),ISNUMBER(O3),ISNUMBER(P3),ISNUMBER(Q3),ISNUMBER(R3),ISNUMBER(S3),ISNUMBER(T3),ISNUMBER(U3),N3>0,O3>0),MIN((INT(N3)*3+ROUND(MOD(N3,1)*10,0))/3,(INT(O3)*3+ROUND(MOD(O3,1)*10,0))/3),"") -> 36.333333 | AA3: =IF(ISNUMBER(Z3),W3*Z3,"") -> 37.325233 | AB3: =IF(ISNUMBER(Z3),X3*Z3,"") -> 26.261733 | AC3: =IF(ISNUMBER(Z3),Y3*Z3,"") -> -2.4016333
A4: Sandy Alcantara | B4: 27 | C4: MIA | D4: P | E4: R | F4: Dominican | G4: 2023 | H4: 45205 | I4: 45743 | J4: 72 | K4: 67 | L4: 72 | M4: 64 | N4: 476.1 | O4: 388.2 | P4: 0.1752 | Q4: 0.1092 | R4: 2.7397 | S4: 4.5386 | T4: 3.2391 | U4: 4.1699 | V4: 18684 | W4: =IF(AND(ISNUMBER(N4),ISNUMBER(O4),ISNUMBER(P4),ISNUMBER(Q4),ISNUMBER(R4),ISNUMBER(S4),ISNUMBER(T4),ISNUMBER(U4),N4>0,O4>0),S4-R4,"") -> 1.7989 | X4: =IF(AND(ISNUMBER(N4),ISNUMBER(O4),ISNUMBER(P4),ISNUMBER(Q4),ISNUMBER(R4),ISNUMBER(S4),ISNUMBER(T4),ISNUMBER(U4),N4>0,O4>0),U4-T4,"") -> 0.9308 | Y4: =IF(AND(ISNUMBER(N4),ISNUMBER(O4),ISNUMBER(P4),ISNUMBER(Q4),ISNUMBER(R4),ISNUMBER(S4),ISNUMBER(T4),ISNUMBER(U4),N4>0,O4>0),Q4-P4,"") -> -0.066 | Z4: =IF(AND(ISNUMBER(N4),ISNUMBER(O4),ISNUMBER(P4),ISNUMBER(Q4),ISNUMBER(R4),ISNUMBER(S4),ISNUMBER(T4),ISNUMBER(U4),N4>0,O4>0),MIN((INT(N4)*3+ROUND(MOD(N4,1)*10,0))/3,(INT(O4)*3+ROUND(MOD(O4,1)*10,0))/3),"") -> 388.66667 | AA4: =IF(ISNUMBER(Z4),W4*Z4,"") -> 699.17247 | AB4: =IF(ISNUMBER(Z4),X4*Z4,"") -> 361.77093 | AC4: =IF(ISNUMBER(Z4),Y4*Z4,"") -> -25.652
A5: Angel Perdomo | B5: 29 | C5: PIT | D5: P | E5: L | F5: Dominican | G5: 2023 | H5: 45205 | I5: 45749 | J5: 22 | K5: 4 | L5: 0 | M5: 0 | N5: 19.2 | O5: 3.1 | P5: 0.102 | Q5: -0.0625 | R5: 8.2373 | S5: 5.4 | T5: 6.4259 | U5: 5.54 | V5: 17759 | W5: =IF(AND(ISNUMBER(N5),ISNUMBER(O5),ISNUMBER(P5),ISNUMBER(Q5),ISNUMBER(R5),ISNUMBER(S5),ISNUMBER(T5),ISNUMBER(U5),N5>0,O5>0),S5-R5,"") -> -2.8373 | X5: =IF(AND(ISNUMBER(N5),ISNUMBER(O5),ISNUMBER(P5),ISNUMBER(Q5),ISNUMBER(R5),ISNUMBER(S5),ISNUMBER(T5),ISNUMBER(U5),N5>0,O5>0),U5-T5,"") -> -0.8859 | Y5: =IF(AND(ISNUMBER(N5),ISNUMBER(O5),ISNUMBER(P5),ISNUMBER(Q5),ISNUMBER(R5),ISNUMBER(S5),ISNUMBER(T5),ISNUMBER(U5),N5>0,O5>0),Q5-P5,"") -> -0.1645 | Z5: =IF(AND(ISNUMBER(N5),ISNUMBER(O5),ISNUMBER(P5),ISNUMBER(Q5),ISNUMBER(R5),ISNUMBER(S5),ISNUMBER(T5),ISNUMBER(U5),N5>0,O5>0),MIN((INT(N5)*3+ROUND(MOD(N5,1)*10,0))/3,(INT(O5)*3+ROUND(MOD(O5,1)*10,0))/3),"") -> 3.3333333 | AA5: =IF(ISNUMBER(Z5),W5*Z5,"") -> -9.4576667 | AB5: =IF(ISNUMBER(Z5),X5*Z5,"") -> -2.953 | AC5: =IF(ISNUMBER(Z5),Y5*Z5,"") -> -0.54833333
A6: Shohei Ohtani | B6: 28 | C6: LAA | D6: P | E6: R | F6: Japan | G6: 2023 | H6: 45188 | I6: 45371 | J6: 53 | K6: 28 | L6: 53 | M6: 28 | N6: 298 | O6: 132.2 | P6: 0.2333 | Q6: 0.2311 | R6: 2.8993 | S6: 2.1709 | T6: 2.9547 | U6: 2.3585 | V6: 19755 | W6: =IF(AND(ISNUMBER(N6),ISNUMBER(O6),ISNUMBER(P6),ISNUMBER(Q6),ISNUMBER(R6),ISNUMBER(S6),ISNUMBER(T6),ISNUMBER(U6),N6>0,O6>0),S6-R6,"") -> -0.7284 | X6: =IF(AND(ISNUMBER(N6),ISNUMBER(O6),ISNUMBER(P6),ISNUMBER(Q6),ISNUMBER(R6),ISNUMBER(S6),ISNUMBER(T6),ISNUMBER(U6),N6>0,O6>0),U6-T6,"") -> -0.5962 | Y6: =IF(AND(ISNUMBER(N6),ISNUMBER(O6),ISNUMBER(P6),ISNUMBER(Q6),ISNUMBER(R6),ISNUMBER(S6),ISNUMBER(T6),ISNUMBER(U6),N6>0,O6>0),Q6-P6,"") -> -0.0022 | Z6: =IF(AND(ISNUMBER(N6),ISNUMBER(O6),ISNUMBER(P6),ISNUMBER(Q6),ISNUMBER(R6),ISNUMBER(S6),ISNUMBER(T6),ISNUMBER(U6),N6>0,O6>0),MIN((INT(N6)*3+ROUND(MOD(N6,1)*10,0))/3,(INT(O6)*3+ROUND(MOD(O6,1)*10,0))/3),"") -> 132.66667 | AA6: =IF(ISNUMBER(Z6),W6*Z6,"") -> -96.6344 | AB6: =IF(ISNUMBER(Z6),X6*Z6,"") -> -79.095867 | AC6: =IF(ISNUMBER(Z6),Y6*Z6,"") -> -0.29186667
A7: Drey Jameson | B7: 25 | C7: ARI | D7: P | E7: R | F7: United States | G7: 2023 | H7: 45170 | I7: 45767 | J7: 4 | K7: 15 | L7: 4 | M7: 0 | N7: 24.1 | O7: 22.1 | P7: 0.1735 | Q7: 0 | R7: 1.4795 | S7: 4.8358 | T7: 3.19 | U7: 4.4087 | V7: 26260 | W7: =IF(AND(ISNUMBER(N7),ISNUMBER(O7),ISNUMBER(P7),ISNUMBER(Q7),ISNUMBER(R7),ISNUMBER(S7),ISNUMBER(T7),ISNUMBER(U7),N7>0,O7>0),S7-R7,"") -> 3.3563 | X7: =IF(AND(ISNUMBER(N7),ISNUMBER(O7),ISNUMBER(P7),ISNUMBER(Q7),ISNUMBER(R7),ISNUMBER(S7),ISNUMBER(T7),ISNUMBER(U7),N7>0,O7>0),U7-T7,"") -> 1.2187 | Y7: =IF(AND(ISNUMBER(N7),ISNUMBER(O7),ISNUMBER(P7),ISNUMBER(Q7),ISNUMBER(R7),ISNUMBER(S7),ISNUMBER(T7),ISNUMBER(U7),N7>0,O7>0),Q7-P7,"") -> -0.1735 | Z7: =IF(AND(ISNUMBER(N7),ISNUMBER(O7),ISNUMBER(P7),ISNUMBER(Q7),ISNUMBER(R7),ISNUMBER(S7),ISNUMBER(T7),ISNUMBER(U7),N7>0,O7>0),MIN((INT(N7)*3+ROUND(MOD(N7,1)*10,0))/3,(INT(O7)*3+ROUND(MOD(O7,1)*10,0))/3),"") -> 22.333333 | AA7: =IF(ISNUMBER(Z7),W7*Z7,"") -> 74.957367 | AB7: =IF(ISNUMBER(Z7),X7*Z7,"") -> 27.217633 | AC7: =IF(ISNUMBER(Z7),Y7*Z7,"") -> -3.8748333
A8: Tony Gonsolin | B8: 29 | C8: LAD | D8: P | E8: R | F8: United States | G8: 2023 | H8: 45170 | I8: 45777 | J8: 48 | K8: 8 | L8: 45 | M8: 7 | N8: 232.2 | O8: 38.2 | P8: 0.1687 | Q8: 0.1279 | R8: 2.437 | S8: 5.819 | T8: 3.3829 | U8: 6.129 | V8: 19388 | W8: =IF(AND(ISNUMBER(N8),ISNUMBER(O8),ISNUMBER(P8),ISNUMBER(Q8),ISNUMBER(R8),ISNUMBER(S8),ISNUMBER(T8),ISNUMBER(U8),N8>0,O8>0),S8-R8,"") -> 3.382 | X8: =IF(AND(ISNUMBER(N8),ISNUMBER(O8),ISNUMBER(P8),ISNUMBER(Q8),ISNUMBER(R8),ISNUMBER(S8),ISNUMBER(T8),ISNUMBER(U8),N8>0,O8>0),U8-T8,"") -> 2.7461 | Y8: =IF(AND(ISNUMBER(N8),ISNUMBER(O8),ISNUMBER(P8),ISNUMBER(Q8),ISNUMBER(R8),ISNUMBER(S8),ISNUMBER(T8),ISNUMBER(U8),N8>0,O8>0),Q8-P8,"") -> -0.0408 | Z8: =IF(AND(ISNUMBER(N8),ISNUMBER(O8),ISNUMBER(P8),ISNUMBER(Q8),ISNUMBER(R8),ISNUMBER(S8),ISNUMBER(T8),ISNUMBER(U8),N8>0,O8>0),MIN((INT(N8)*3+ROUND(MOD(N8,1)*10,0))/3,(INT(O8)*3+ROUND(MOD(O8,1)*10,0))/3),"") -> 38.666667 | AA8: =IF(ISNUMBER(Z8),W8*Z8,"") -> 130.77067 | AB8: =IF(ISNUMBER(Z8),X8*Z8,"") -> 106.18253 | AC8: =IF(ISNUMBER(Z8),Y8*Z8,"") -> -1.5776
A9: Shane McClanahan | B9: 26 | C9: TB | D9: P | E9: L | F9: United States | G9: 2023 | H9: 45159 | I9: 46112 | J9: 53 | K9: 24 | L9: 53 | M9: 24 | N9: 289.2 | O9: 118 | P9: 0.2245 | Q9: 0.1376 | R9: 2.9206 | S9: 3.3559 | T9: 3.132 | U9: 3.5 | V9: 21483 | W9: =IF(AND(ISNUMBER(N9),ISNUMBER(O9),ISNUMBER(P9),ISNUMBER(Q9),ISNUMBER(R9),ISNUMBER(S9),ISNUMBER(T9),ISNUMBER(U9),N9>0,O9>0),S9-R9,"") -> 0.4353 | X9: =IF(AND(ISNUMBER(N9),ISNUMBER(O9),ISNUMBER(P9),ISNUMBER(Q9),ISNUMBER(R9),ISNUMBER(S9),ISNUMBER(T9),ISNUMBER(U9),N9>0,O9>0),U9-T9,"") -> 0.368 | Y9: =IF(AND(ISNUMBER(N9),ISNUMBER(O9),ISNUMBER(P9),ISNUMBER(Q9),ISNUMBER(R9),ISNUMBER(S9),ISNUMBER(T9),ISNUMBER(U9),N9>0,O9>0),Q9-P9,"") -> -0.0869 | Z9: =IF(AND(ISNUMBER(N9),ISNUMBER(O9),ISNUMBER(P9),ISNUMBER(Q9),ISNUMBER(R9),ISNUMBER(S9),ISNUMBER(T9),ISNUMBER(U9),N9>0,O9>0),MIN((INT(N9)*3+ROUND(MOD(N9,1)*10,0))/3,(INT(O9)*3+ROUND(MOD(O9,1)*10,0))/3),"") -> 118 | AA9: =IF(ISNUMBER(Z9),W9*Z9,"") -> 51.3654 | AB9: =IF(ISNUMBER(Z9),X9*Z9,"") -> 43.424 | AC9: =IF(ISNUMBER(Z9),Y9*Z9,"") -> -10.2542
A10: Liam Hendriks | B10: 34 | C10: CHW | D10: P | E10: R | F10: Australia | G10: 2023 | H10: 45140 | I10: 45767 | J10: 151 | K10: 14 | L10: 0 | M10: 0 | N10: 154 | O10: 13.2 | P10: 0.3519 | Q10: 0.0847 | R10: 2.513 | S10: 6.5854 | T10: 2.2699 | U10: 5.04 | V10: 3548 | W10: =IF(AND(ISNUMBER(N10),ISNUMBER(O10),ISNUMBER(P10),ISNUMBER(Q10),ISNUMBER(R10),ISNUMBER(S10),ISNUMBER(T10),ISNUMBER(U10),N10>0,O10>0),S10-R10,"") -> 4.0724 | X10: =IF(AND(ISNUMBER(N10),ISNUMBER(O10),ISNUMBER(P10),ISNUMBER(Q10),ISNUMBER(R10),ISNUMBER(S10),ISNUMBER(T10),ISNUMBER(U10),N10>0,O10>0),U10-T10,"") -> 2.7701 | Y10: =IF(AND(ISNUMBER(N10),ISNUMBER(O10),ISNUMBER(P10),ISNUMBER(Q10),ISNUMBER(R10),ISNUMBER(S10),ISNUMBER(T10),ISNUMBER(U10),N10>0,O10>0),Q10-P10,"") -> -0.2672 | Z10: =IF(AND(ISNUMBER(N10),ISNUMBER(O10),ISNUMBER(P10),ISNUMBER(Q10),ISNUMBER(R10),ISNUMBER(S10),ISNUMBER(T10),ISNUMBER(U10),N10>0,O10>0),MIN((INT(N10)*3+ROUND(MOD(N10,1)*10,0))/3,(INT(O10)*3+ROUND(MOD(O10,1)*10,0))/3),"") -> 13.666667 | AA10: =IF(ISNUMBER(Z10),W10*Z10,"") -> 55.656133 | AB10: =IF(ISNUMBER(Z10),X10*Z10,"") -> 37.858033 | AC10: =IF(ISNUMBER(Z10),Y10*Z10,"") -> -3.6517333
A11: Reiss Knehr | B11: 26 | C11: SD | D11: P | E11: R | F11: United States | G11: 2023 | H11: 45139 | J11: 17 | K11: NULL | L11: 6 | M11: NULL | N11: 42.2 | O11: NULL | P11: 0.0319 | Q11: NULL | R11: 4.6406 | S11: NULL | T11: 4.7678 | U11: NULL | V11: 21541 | W11: =IF(AND(ISNUMBER(N11),ISNUMBER(O11),ISNUMBER(P11),ISNUMBER(Q11),ISNUMBER(R11),ISNUMBER(S11),ISNUMBER(T11),ISNUMBER(U11),N11>0,O11>0),S11-R11,"") | X11: =IF(AND(ISNUMBER(N11),ISNUMBER(O11),ISNUMBER(P11),ISNUMBER(Q11),ISNUMBER(R11),ISNUMBER(S11),ISNUMBER(T11),ISNUMBER(U11),N11>0,O11>0),U11-T11,"") | Y11: =IF(AND(ISNUMBER(N11),ISNUMBER(O11),ISNUMBER(P11),ISNUMBER(Q11),ISNUMBER(R11),ISNUMBER(S11),ISNUMBER(T11),ISNUMBER(U11),N11>0,O11>0),Q11-P11,"") | Z11: =IF(AND(ISNUMBER(N11),ISNUMBER(O11),ISNUMBER(P11),ISNUMBER(Q11),ISNUMBER(R11),ISNUMBER(S11),ISNUMBER(T11),ISNUMBER(U11),N11>0,O11>0),MIN((INT(N11)*3+ROUND(MOD(N11,1)*10,0))/3,(INT(O11)*3+ROUND(MOD(O11,1)*10,0))/3),"") | AA11: =IF(ISNUMBER(Z11),W11*Z11,"") | AB11: =IF(ISNUMBER(Z11),X11*Z11,"") | AC11: =IF(ISNUMBER(Z11),Y11*Z11,"")
A12: Antonio Senzatela | B12: 28 | C12: COL | D12: P | E12: R | F12: Venezuela | G12: 2023 | H12: 45133 | I12: 45551 | J12: 59 | K12: 90 | L12: 59 | M12: 26 | N12: 322.1 | O12: 215.2 | P12: 0.0916 | Q12: 0.06 | R12: 4.3837 | S12: 5.7589 | T12: 3.9544 | U12: 4.9595 | V12: 15488 | W12: =IF(AND(ISNUMBER(N12),ISNUMBER(O12),ISNUMBER(P12),ISNUMBER(Q12),ISNUMBER(R12),ISNUMBER(S12),ISNUMBER(T12),ISNUMBER(U12),N12>0,O12>0),S12-R12,"") -> 1.3752 | X12: =IF(AND(ISNUMBER(N12),ISNUMBER(O12),ISNUMBER(P12),ISNUMBER(Q12),ISNUMBER(R12),ISNUMBER(S12),ISNUMBER(T12),ISNUMBER(U12),N12>0,O12>0),U12-T12,"") -> 1.0051 | Y12: =IF(AND(ISNUMBER(N12),ISNUMBER(O12),ISNUMBER(P12),ISNUMBER(Q12),ISNUMBER(R12),ISNUMBER(S12),ISNUMBER(T12),ISNUMBER(U12),N12>0,O12>0),Q12-P12,"") -> -0.0316 | Z12: =IF(AND(ISNUMBER(N12),ISNUMBER(O12),ISNUMBER(P12),ISNUMBER(Q12),ISNUMBER(R12),ISNUMBER(S12),ISNUMBER(T12),ISNUMBER(U12),N12>0,O12>0),MIN((INT(N12)*3+ROUND(MOD(N12,1)*10,0))/3,(INT(O12)*3+ROUND(MOD(O12,1)*10,0))/3),"") -> 215.66667 | AA12: =IF(ISNUMBER(Z12),W12*Z12,"") -> 296.5848 | AB12: =IF(ISNUMBER(Z12),X12*Z12,"") -> 216.76657 | AC12: =IF(ISNUMBER(Z12),Y12*Z12,"") -> -6.8150667
A13: Jose De Leon | B13: 30 | C13: MIN | D13: P | E13: R | F13: Puerto Rico | G13: 2023 | H13: 45126 | I13: 45928 | J13: 14 | K13: 1 | L13: 2 | M13: 1 | N13: 24.1 | O13: 6.2 | P13: 0.1667 | Q13: 0.1786 | R13: 10.726 | S13: 4.05 | T13: 5.2673 | U13: 4.04 | V13: 15463 | W13: =IF(AND(ISNUMBER(N13),ISNUMBER(O13),ISNUMBER(P13),ISNUMBER(Q13),ISNUMBER(R13),ISNUMBER(S13),ISNUMBER(T13),ISNUMBER(U13),N13>0,O13>0),S13-R13,"") -> -6.676 | X13: =IF(AND(ISNUMBER(N13),ISNUMBER(O13),ISNUMBER(P13),ISNUMBER(Q13),ISNUMBER(R13),ISNUMBER(S13),ISNUMBER(T13),ISNUMBER(U13),N13>0,O13>0),U13-T13,"") -> -1.2273 | Y13: =IF(AND(ISNUMBER(N13),ISNUMBER(O13),ISNUMBER(P13),ISNUMBER(Q13),ISNUMBER(R13),ISNUMBER(S13),ISNUMBER(T13),ISNUMBER(U13),N13>0,O13>0),Q13-P13,"") -> 0.0119 | Z13: =IF(AND(ISNUMBER(N13),ISNUMBER(O13),ISNUMBER(P13),ISNUMBER(Q13),ISNUMBER(R13),ISNUMBER(S13),ISNUMBER(T13),ISNUMBER(U13),N13>0,O13>0),MIN((INT(N13)*3+ROUND(MOD(N13,1)*10,0))/3,(INT(O13)*3+ROUND(MOD(O13,1)*10,0))/3),"") -> 6.6666667 | AA13: =IF(ISNUMBER(Z13),W13*Z13,"") -> -44.506667 | AB13: =IF(ISNUMBER(Z13),X13*Z13,"") -> -8.182 | AC13: =IF(ISNUMBER(Z13),Y13*Z13,"") -> 0.079333333
A14: Dustin May | B14: 25 | C14: LAD | D14: P | E14: R | F14: United States | G14: 2023 | H14: 45125 | I14: 45748 | J14: 23 | K14: 56 | L14: 21 | M14: 54 | N14: 109 | O14: 278 | P14: 0.1622 | Q14: 0.1336 | R14: 3.1376 | S14: 4.8237 | T14: 4.2754 | U14: 4.225 | V14: 19716 | W14: =IF(AND(ISNUMBER(N14),ISNUMBER(O14),ISNUMBER(P14),ISNUMBER(Q14),ISNUMBER(R14),ISNUMBER(S14),ISNUMBER(T14),ISNUMBER(U14),N14>0,O14>0),S14-R14,"") -> 1.6861 | X14: =IF(AND(ISNUMBER(N14),ISNUMBER(O14),ISNUMBER(P14),ISNUMBER(Q14),ISNUMBER(R14),ISNUMBER(S14),ISNUMBER(T14),ISNUMBER(U14),N14>0,O14>0),U14-T14,"") -> -0.0504 | Y14: =IF(AND(ISNUMBER(N14),ISNUMBER(O14),ISNUMBER(P14),ISNUMBER(Q14),ISNUMBER(R14),ISNUMBER(S14),ISNUMBER(T14),ISNUMBER(U14),N14>0,O14>0),Q14-P14,"") -> -0.0286 | Z14: =IF(AND(ISNUMBER(N14),ISNUMBER(O14),ISNUMBER(P14),ISNUMBER(Q14),ISNUMBER(R14),ISNUMBER(S14),ISNUMBER(T14),ISNUMBER(U14),N14>0,O14>0),MIN((INT(N14)*3+ROUND(MOD(N14,1)*10,0))/3,(INT(O14)*3+ROUND(MOD(O14,1)*10,0))/3),"") -> 109 | AA14: =IF(ISNUMBER(Z14),W14*Z14,"") -> 183.7849 | AB14: =IF(ISNUMBER(Z14),X14*Z14,"") -> -5.4936 | AC14: =IF(ISNUMBER(Z14),Y14*Z14,"") -> -3.1174
A15: Reiver Sanmartin | B15: 27 | C15: CIN | D15: P | E15: R | F15: Colombia | G15: 2023 | H15: 45114 | I15: 45902 | J15: 47 | K15: 25 | L15: 6 | M15: 0 | N15: 68.2 | O15: 23 | P15: 0.0891 | Q15: 0.099 | R15: 5.5049 | S15: 3.913 | T15: 4.2986 | U15: 4.2745 | V15: 19754 | W15: =IF(AND(ISNUMBER(N15),ISNUMBER(O15),ISNUMBER(P15),ISNUMBER(Q15),ISNUMBER(R15),ISNUMBER(S15),ISNUMBER(T15),ISNUMBER(U15),N15>0,O15>0),S15-R15,"") -> -1.5919 | X15: =IF(AND(ISNUMBER(N15),ISNUMBER(O15),ISNUMBER(P15),ISNUMBER(Q15),ISNUMBER(R15),ISNUMBER(S15),ISNUMBER(T15),ISNUMBER(U15),N15>0,O15>0),U15-T15,"") -> -0.0241 | Y15: =IF(AND(ISNUMBER(N15),ISNUMBER(O15),ISNUMBER(P15),ISNUMBER(Q15),ISNUMBER(R15),ISNUMBER(S15),ISNUMBER(T15),ISNUMBER(U15),N15>0,O15>0),Q15-P15,"") -> 0.0099 | Z15: =IF(AND(ISNUMBER(N15),ISNUMBER(O15),ISNUMBER(P15),ISNUMBER(Q15),ISNUMBER(R15),ISNUMBER(S15),ISNUMBER(T15),ISNUMBER(U15),N15>0,O15>0),MIN((INT(N15)*3+ROUND(MOD(N15,1)*10,0))/3,(INT(O15)*3+ROUND(MOD(O15,1)*10,0))/3),"") -> 23 | AA15: =IF(ISNUMBER(Z15),W15*Z15,"") -> -36.6137 | AB15: =IF(ISNUMBER(Z15),X15*Z15,"") -> -0.5543 | AC15: =IF(ISNUMBER(Z15),Y15*Z15,"") -> 0.2277
A16: Penn Murfee | B16: 29 | C16: SEA | D16: P | E16: R | F16: United States | G16: 2023 | H16: 45108 | I16: 45743 | J16: 64 | K16: 15 | L16: 1 | M16: 0 | N16: 69.1 | O16: 12.2 | P16: 0.2132 | Q16: 0.127 | R16: 2.9856 | S16: 7.8158 | T16: 3.1 | U16: 5.58 | V16: 25174 | W16: =IF(AND(ISNUMBER(N16),ISNUMBER(O16),ISNUMBER(P16),ISNUMBER(Q16),ISNUMBER(R16),ISNUMBER(S16),ISNUMBER(T16),ISNUMBER(U16),N16>0,O16>0),S16-R16,"") -> 4.8302 | X16: =IF(AND(ISNUMBER(N16),ISNUMBER(O16),ISNUMBER(P16),ISNUMBER(Q16),ISNUMBER(R16),ISNUMBER(S16),ISNUMBER(T16),ISNUMBER(U16),N16>0,O16>0),U16-T16,"") -> 2.48 | Y16: =IF(AND(ISNUMBER(N16),ISNUMBER(O16),ISNUMBER(P16),ISNUMBER(Q16),ISNUMBER(R16),ISNUMBER(S16),ISNUMBER(T16),ISNUMBER(U16),N16>0,O16>0),Q16-P16,"") -> -0.0862 | Z16: =IF(AND(ISNUMBER(N16),ISNUMBER(O16),ISNUMBER(P16),ISNUMBER(Q16),ISNUMBER(R16),ISNUMBER(S16),ISNUMBER(T16),ISNUMBER(U16),N16>0,O16>0),MIN((INT(N16)*3+ROUND(MOD(N16,1)*10,0))/3,(INT(O16)*3+ROUND(MOD(O16,1)*10,0))/3),"") -> 12.666667 | AA16: =IF(ISNUMBER(Z16),W16*Z16,"") -> 61.182533 | AB16: =IF(ISNUMBER(Z16),X16*Z16,"") -> 31.413333 | AC16: =IF(ISNUMBER(Z16),Y16*Z16,"") -> -1.0918667
A17: Matthew Boyd | B17: 32 | C17: DET | D17: P | E17: L | F17: United States | G17: 2023 | H17: 45105 | I17: 45517 | J17: 37 | K17: 61 | L17: 27 | M17: 61 | N17: 152.1 | O17: 346 | P17: 0.1316 | Q17: 0.1439 | R17: 4.7856 | S17: 3.4075 | T17: 4.6857 | U17: 3.8137 | V17: 15440 | W17: =IF(AND(ISNUMBER(N17),ISNUMBER(O17),ISNUMBER(P17),ISNUMBER(Q17),ISNUMBER(R17),ISNUMBER(S17),ISNUMBER(T17),ISNUMBER(U17),N17>0,O17>0),S17-R17,"") -> -1.3781 | X17: =IF(AND(ISNUMBER(N17),ISNUMBER(O17),ISNUMBER(P17),ISNUMBER(Q17),ISNUMBER(R17),ISNUMBER(S17),ISNUMBER(T17),ISNUMBER(U17),N17>0,O17>0),U17-T17,"") -> -0.872 | Y17: =IF(AND(ISNUMBER(N17),ISNUMBER(O17),ISNUMBER(P17),ISNUMBER(Q17),ISNUMBER(R17),ISNUMBER(S17),ISNUMBER(T17),ISNUMBER(U17),N17>0,O17>0),Q17-P17,"") -> 0.0123 | Z17: =IF(AND(ISNUMBER(N17),ISNUMBER(O17),ISNUMBER(P17),ISNUMBER(Q17),ISNUMBER(R17),ISNUMBER(S17),ISNUMBER(T17),ISNUMBER(U17),N17>0,O17>0),MIN((INT(N17)*3+ROUND(MOD(N17,1)*10,0))/3,(INT(O17)*3+ROUND(MOD(O17,1)*10,0))/3),"") -> 152.33333 | AA17: =IF(ISNUMBER(Z17),W17*Z17,"") -> -209.93057 | AB17: =IF(ISNUMBER(Z17),X17*Z17,"") -> -132.83467 | AC17: =IF(ISNUMBER(Z17),Y17*Z17,"") -> 1.8737
A18: Jacob deGrom | B18: 35 | C18: TEX | D18: P | E18: R | F18: United States | G18: 2023 | H18: 45089 | I18: 45548 | J18: 38 | K18: 64 | L18: 38 | M18: 64 | N18: 224.1 | O18: 346 | P18: 0.3791 | Q18: 0.2288 | R18: 2.0461 | S18: 3.5116 | T18: 1.8044 | U18: 3.3501 | V18: 10954 | W18: =IF(AND(ISNUMBER(N18),ISNUMBER(O18),ISNUMBER(P18),ISNUMBER(Q18),ISNUMBER(R18),ISNUMBER(S18),ISNUMBER(T18),ISNUMBER(U18),N18>0,O18>0),S18-R18,"") -> 1.4655 | X18: =IF(AND(ISNUMBER(N18),ISNUMBER(O18),ISNUMBER(P18),ISNUMBER(Q18),ISNUMBER(R18),ISNUMBER(S18),ISNUMBER(T18),ISNUMBER(U18),N18>0,O18>0),U18-T18,"") -> 1.5457 | Y18: =IF(AND(ISNUMBER(N18),ISNUMBER(O18),ISNUMBER(P18),ISNUMBER(Q18),ISNUMBER(R18),ISNUMBER(S18),ISNUMBER(T18),ISNUMBER(U18),N18>0,O18>0),Q18-P18,"") -> -0.1503 | Z18: =IF(AND(ISNUMBER(N18),ISNUMBER(O18),ISNUMBER(P18),ISNUMBER(Q18),ISNUMBER(R18),ISNUMBER(S18),ISNUMBER(T18),ISNUMBER(U18),N18>0,O18>0),MIN((INT(N18)*3+ROUND(MOD(N18,1)*10,0))/3,(INT(O18)*3+ROUND(MOD(O18,1)*10,0))/3),"") -> 224.33333 | AA18: =IF(ISNUMBER(Z18),W18*Z18,"") -> 328.7605 | AB18: =IF(ISNUMBER(Z18),X18*Z18,"") -> 346.75203 | AC18: =IF(ISNUMBER(Z18),Y18*Z18,"") -> -33.7173
A19: Connor Overton | B19: 29 | C19: CIN | D19: P | E19: R | F19: United States | G19: 2023 | H19: 45069 | J19: 15 | K19: NULL | L19: 7 | M19: NULL | N19: 48.1 | O19: NULL | P19: 0.0695 | Q19: NULL | R19: 3.3517 | S19: NULL | T19: 3.733 | U19: NULL | V19: 18376 | W19: =IF(AND(ISNUMBER(N19),ISNUMBER(O19),ISNUMBER(P19),ISNUMBER(Q19),ISNUMBER(R19),ISNUMBER(S19),ISNUMBER(T19),ISNUMBER(U19),N19>0,O19>0),S19-R19,"") | X19: =IF(AND(ISNUMBER(N19),ISNUMBER(O19),ISNUMBER(P19),ISNUMBER(Q19),ISNUMBER(R19),ISNUMBER(S19),ISNUMBER(T19),ISNUMBER(U19),N19>0,O19>0),U19-T19,"") | Y19: =IF(AND(ISNUMBER(N19),ISNUMBER(O19),ISNUMBER(P19),ISNUMBER(Q19),ISNUMBER(R19),ISNUMBER(S19),ISNUMBER(T19),ISNUMBER(U19),N19>0,O19>0),Q19-P19,"") | Z19: =IF(AND(ISNUMBER(N19),ISNUMBER(O19),ISNUMBER(P19),ISNUMBER(Q19),ISNUMBER(R19),ISNUMBER(S19),ISNUMBER(T19),ISNUMBER(U19),N19>0,O19>0),MIN((INT(N19)*3+ROUND(MOD(N19,1)*10,0))/3,(INT(O19)*3+ROUND(MOD(O19,1)*10,0))/3),"") | AA19: =IF(ISNUMBER(Z19),W19*Z19,"") | AB19: =IF(ISNUMBER(Z19),X19*Z19,"") | AC19: =IF(ISNUMBER(Z19),Y19*Z19,"")
A20: Tyler Mahle | B20: 28 | C20: MIN | D20: P | E20: R | F20: United States | G20: 2023 | H20: 45068 | I20: 45510 | J20: 66 | K20: 46 | L20: 65 | M20: 46 | N20: 348.1 | O20: 248.1 | P20: 0.1832 | Q20: 0.1319 | R20: 3.9531 | S20: 3.4067 | T20: 3.8352 | U20: 3.7639 | V20: 16358 | W20: =IF(AND(ISNUMBER(N20),ISNUMBER(O20),ISNUMBER(P20),ISNUMBER(Q20),ISNUMBER(R20),ISNUMBER(S20),ISNUMBER(T20),ISNUMBER(U20),N20>0,O20>0),S20-R20,"") -> -0.5464 | X20: =IF(AND(ISNUMBER(N20),ISNUMBER(O20),ISNUMBER(P20),ISNUMBER(Q20),ISNUMBER(R20),ISNUMBER(S20),ISNUMBER(T20),ISNUMBER(U20),N20>0,O20>0),U20-T20,"") -> -0.0713 | Y20: =IF(AND(ISNUMBER(N20),ISNUMBER(O20),ISNUMBER(P20),ISNUMBER(Q20),ISNUMBER(R20),ISNUMBER(S20),ISNUMBER(T20),ISNUMBER(U20),N20>0,O20>0),Q20-P20,"") -> -0.0513 | Z20: =IF(AND(ISNUMBER(N20),ISNUMBER(O20),ISNUMBER(P20),ISNUMBER(Q20),ISNUMBER(R20),ISNUMBER(S20),ISNUMBER(T20),ISNUMBER(U20),N20>0,O20>0),MIN((INT(N20)*3+ROUND(MOD(N20,1)*10,0))/3,(INT(O20)*3+ROUND(MOD(O20,1)*10,0))/3),"") -> 248.33333 | AA20: =IF(ISNUMBER(Z20),W20*Z20,"") -> -135.68933 | AB20: =IF(ISNUMBER(Z20),X20*Z20,"") -> -17.706167 | AC20: =IF(ISNUMBER(Z20),Y20*Z20,"") -> -12.7395
A21: Luis Garcia | B21: 26 | C21: HOU | D21: P | E21: R | F21: Venezuela | G21: 2023 | H21: 45065 | I21: 45901 | W21: =IF(AND(ISNUMBER(N21),ISNUMBER(O21),ISNUMBER(P21),ISNUMBER(Q21),ISNUMBER(R21),ISNUMBER(S21),ISNUMBER(T21),ISNUMBER(U21),N21>0,O21>0),S21-R21,"") | X21: =IF(AND(ISNUMBER(N21),ISNUMBER(O21),ISNUMBER(P21),ISNUMBER(Q21),ISNUMBER(R21),ISNUMBER(S21),ISNUMBER(T21),ISNUMBER(U21),N21>0,O21>0),U21-T21,"") | Y21: =IF(AND(ISNUMBER(N21),ISNUMBER(O21),ISNUMBER(P21),ISNUMBER(Q21),ISNUMBER(R21),ISNUMBER(S21),ISNUMBER(T21),ISNUMBER(U21),N21>0,O21>0),Q21-P21,"") | Z21: =IF(AND(ISNUMBER(N21),ISNUMBER(O21),ISNUMBER(P21),ISNUMBER(Q21),ISNUMBER(R21),ISNUMBER(S21),ISNUMBER(T21),ISNUMBER(U21),N21>0,O21>0),MIN((INT(N21)*3+ROUND(MOD(N21,1)*10,0))/3,(INT(O21)*3+ROUND(MOD(O21,1)*10,0))/3),"") | AA21: =IF(ISNUMBER(Z21),W21*Z21,"") | AB21: =IF(ISNUMBER(Z21),X21*Z21,"") | AC21: =IF(ISNUMBER(Z21),Y21*Z21,"")
A22: Jose Quijada | B22: 27 | C22: LAA | D22: P | E22: L | F22: Venezuela | G22: 2023 | H22: 45063 | I22: 45497 | J22: 74 | K22: 24 | L22: 0 | M22: 0 | N22: 70 | O22: 20.2 | P22: 0.194 | Q22: 0.087 | R22: 4.3714 | S22: 3.0484 | T22: 3.6798 | U22: 4.2252 | V22: 19200 | W22: =IF(AND(ISNUMBER(N22),ISNUMBER(O22),ISNUMBER(P22),ISNUMBER(Q22),ISNUMBER(R22),ISNUMBER(S22),ISNUMBER(T22),ISNUMBER(U22),N22>0,O22>0),S22-R22,"") -> -1.323 | X22: =IF(AND(ISNUMBER(N22),ISNUMBER(O22),ISNUMBER(P22),ISNUMBER(Q22),ISNUMBER(R22),ISNUMBER(S22),ISNUMBER(T22),ISNUMBER(U22),N22>0,O22>0),U22-T22,"") -> 0.5454 | Y22: =IF(AND(ISNUMBER(N22),ISNUMBER(O22),ISNUMBER(P22),ISNUMBER(Q22),ISNUMBER(R22),ISNUMBER(S22),ISNUMBER(T22),ISNUMBER(U22),N22>0,O22>0),Q22-P22,"") -> -0.107 | Z22: =IF(AND(ISNUMBER(N22),ISNUMBER(O22),ISNUMBER(P22),ISNUMBER(Q22),ISNUMBER(R22),ISNUMBER(S22),ISNUMBER(T22),ISNUMBER(U22),N22>0,O22>0),MIN((INT(N22)*3+ROUND(MOD(N22,1)*10,0))/3,(INT(O22)*3+ROUND(MOD(O22,1)*10,0))/3),"") -> 20.666667 | AA22: =IF(ISNUMBER(Z22),W22*Z22,"") -> -27.342 | AB22: =IF(ISNUMBER(Z22),X22*Z22,"") -> 11.2716 | AC22: =IF(ISNUMBER(Z22),Y22*Z22,"") -> -2.2113333
A23: Austin Warren | B23: 27 | C23: LAA | D23: P | E23: R | F23: United States | G23: 2023 | H23: 45063 | I23: 45532 | J23: 30 | K23: 52 | L23: 0 | M23: 2 | N23: 36.1 | O23: 70.1 | P23: 0.1234 | Q23: 0.1301 | R23: 3.4679 | S23: 3.327 | T23: 3.53 | U23: 4.1083 | V23: 24937 | W23: =IF(AND(ISNUMBER(N23),ISNUMBER(O23),ISNUMBER(P23),ISNUMBER(Q23),ISNUMBER(R23),ISNUMBER(S23),ISNUMBER(T23),ISNUMBER(U23),N23>0,O23>0),S23-R23,"") -> -0.1409 | X23: =IF(AND(ISNUMBER(N23),ISNUMBER(O23),ISNUMBER(P23),ISNUMBER(Q23),ISNUMBER(R23),ISNUMBER(S23),ISNUMBER(T23),ISNUMBER(U23),N23>0,O23>0),U23-T23,"") -> 0.5783 | Y23: =IF(AND(ISNUMBER(N23),ISNUMBER(O23),ISNUMBER(P23),ISNUMBER(Q23),ISNUMBER(R23),ISNUMBER(S23),ISNUMBER(T23),ISNUMBER(U23),N23>0,O23>0),Q23-P23,"") -> 0.0067 | Z23: =IF(AND(ISNUMBER(N23),ISNUMBER(O23),ISNUMBER(P23),ISNUMBER(Q23),ISNUMBER(R23),ISNUMBER(S23),ISNUMBER(T23),ISNUMBER(U23),N23>0,O23>0),MIN((INT(N23)*3+ROUND(MOD(N23,1)*10,0))/3,(INT(O23)*3+ROUND(MOD(O23,1)*10,0))/3),"") -> 36.333333 | AA23: =IF(ISNUMBER(Z23),W23*Z23,"") -> -5.1193667 | AB23: =IF(ISNUMBER(Z23),X23*Z23,"") -> 21.011567 | AC23: =IF(ISNUMBER(Z23),Y23*Z23,"") -> 0.24343333
A24: German Marquez | B24: 28 | C24: COL | D24: P | E24: R | F24: Venezuela | G24: 2023 | H24: 45058 | I24: 45487 | J24: 76 | K24: 40 | L24: 76 | M24: 37 | N24: 443.1 | O24: 183.1 | P24: 0.1315 | Q24: 0.0555 | R24: 4.5068 | S24: 6.2836 | T24: 4.1015 | U24: 5.853 | V24: 15038 | W24: =IF(AND(ISNUMBER(N24),ISNUMBER(O24),ISNUMBER(P24),ISNUMBER(Q24),ISNUMBER(R24),ISNUMBER(S24),ISNUMBER(T24),ISNUMBER(U24),N24>0,O24>0),S24-R24,"") -> 1.7768 | X24: =IF(AND(ISNUMBER(N24),ISNUMBER(O24),ISNUMBER(P24),ISNUMBER(Q24),ISNUMBER(R24),ISNUMBER(S24),ISNUMBER(T24),ISNUMBER(U24),N24>0,O24>0),U24-T24,"") -> 1.7515 | Y24: =IF(AND(ISNUMBER(N24),ISNUMBER(O24),ISNUMBER(P24),ISNUMBER(Q24),ISNUMBER(R24),ISNUMBER(S24),ISNUMBER(T24),ISNUMBER(U24),N24>0,O24>0),Q24-P24,"") -> -0.076 | Z24: =IF(AND(ISNUMBER(N24),ISNUMBER(O24),ISNUMBER(P24),ISNUMBER(Q24),ISNUMBER(R24),ISNUMBER(S24),ISNUMBER(T24),ISNUMBER(U24),N24>0,O24>0),MIN((INT(N24)*3+ROUND(MOD(N24,1)*10,0))/3,(INT(O24)*3+ROUND(MOD(O24,1)*10,0))/3),"") -> 183.33333 | AA24: =IF(ISNUMBER(Z24),W24*Z24,"") -> 325.74667 | AB24: =IF(ISNUMBER(Z24),X24*Z24,"") -> 321.10833 | AC24: =IF(ISNUMBER(Z24),Y24*Z24,"") -> -13.933333
A25: Lou Trivino | B25: 31 | C25: NYY | D25: P | E25: R | F25: United States | G25: 2023 | H25: 45049 | I25: 45745 | J25: 155 | K25: 52 | L25: 0 | M25: 2 | N25: 150.2 | O25: 53.2 | P25: 0.1409 | Q25: 0.0782 | R25: 3.7633 | S25: 5.1988 | T25: 3.7483 | U25: 4.976 | V25: 15043 | W25: =IF(AND(ISNUMBER(N25),ISNUMBER(O25),ISNUMBER(P25),ISNUMBER(Q25),ISNUMBER(R25),ISNUMBER(S25),ISNUMBER(T25),ISNUMBER(U25),N25>0,O25>0),S25-R25,"") -> 1.4355 | X25: =IF(AND(ISNUMBER(N25),ISNUMBER(O25),ISNUMBER(P25),ISNUMBER(Q25),ISNUMBER(R25),ISNUMBER(S25),ISNUMBER(T25),ISNUMBER(U25),N25>0,O25>0),U25-T25,"") -> 1.2277 | Y25: =IF(AND(ISNUMBER(N25),ISNUMBER(O25),ISNUMBER(P25),ISNUMBER(Q25),ISNUMBER(R25),ISNUMBER(S25),ISNUMBER(T25),ISNUMBER(U25),N25>0,O25>0),Q25-P25,"") -> -0.0627 | Z25: =IF(AND(ISNUMBER(N25),ISNUMBER(O25),ISNUMBER(P25),ISNUMBER(Q25),ISNUMBER(R25),ISNUMBER(S25),ISNUMBER(T25),ISNUMBER(U25),N25>0,O25>0),MIN((INT(N25)*3+ROUND(MOD(N25,1)*10,0))/3,(INT(O25)*3+ROUND(MOD(O25,1)*10,0))/3),"") -> 53.666667 | AA25: =IF(ISNUMBER(Z25),W25*Z25,"") -> 77.0385 | AB25: =IF(ISNUMBER(Z25),X25*Z25,"") -> 65.886567 | AC25: =IF(ISNUMBER(Z25),Y25*Z25,"") -> -3.3649
A26: Robbie Ray | B26: 31 | C26: SEA | D26: P | E26: L | F26: United States | G26: 2023 | H26: 45049 | I26: 45497 | J26: 76 | K26: 70 | L26: 75 | M26: 69 | N26: 434 | O26: 378.2 | P26: 0.2051 | Q26: 0.1242 | R26: 3.6705 | S26: 3.7077 | T26: 4.2292 | U26: 4.3459 | V26: 11486 | W26: =IF(AND(ISNUMBER(N26),ISNUMBER(O26),ISNUMBER(P26),ISNUMBER(Q26),ISNUMBER(R26),ISNUMBER(S26),ISNUMBER(T26),ISNUMBER(U26),N26>0,O26>0),S26-R26,"") -> 0.0372 | X26: =IF(AND(ISNUMBER(N26),ISNUMBER(O26),ISNUMBER(P26),ISNUMBER(Q26),ISNUMBER(R26),ISNUMBER(S26),ISNUMBER(T26),ISNUMBER(U26),N26>0,O26>0),U26-T26,"") -> 0.1167 | Y26: =IF(AND(ISNUMBER(N26),ISNUMBER(O26),ISNUMBER(P26),ISNUMBER(Q26),ISNUMBER(R26),ISNUMBER(S26),ISNUMBER(T26),ISNUMBER(U26),N26>0,O26>0),Q26-P26,"") -> -0.0809 | Z26: =IF(AND(ISNUMBER(N26),ISNUMBER(O26),ISNUMBER(P26),ISNUMBER(Q26),ISNUMBER(R26),ISNUMBER(S26),ISNUMBER(T26),ISNUMBER(U26),N26>0,O26>0),MIN((INT(N26)*3+ROUND(MOD(N26,1)*10,0))/3,(INT(O26)*3+ROUND(MOD(O26,1)*10,0))/3),"") -> 378.66667 | AA26: =IF(ISNUMBER(Z26),W26*Z26,"") -> 14.0864 | AB26: =IF(ISNUMBER(Z26),X26*Z26,"") -> 44.1904 | AC26: =IF(ISNUMBER(Z26),Y26*Z26,"") -> -30.634133
A27: Easton McGee | B27: 25 | C27: SEA | D27: P | E27: R | F27: United States | G27: 2023 | H27: 45047 | I27: 45798 | J27: 1 | K27: 18 | L27: 0 | M27: 0 | N27: 3 | O27: 26 | P27: 0.0714 | Q27: 0.1053 | R27: 0 | S27: 6.2308 | T27: 2.45 | U27: 4.5821 | V27: 22176 | W27: =IF(AND(ISNUMBER(N27),ISNUMBER(O27),ISNUMBER(P27),ISNUMBER(Q27),ISNUMBER(R27),ISNUMBER(S27),ISNUMBER(T27),ISNUMBER(U27),N27>0,O27>0),S27-R27,"") -> 6.2308 | X27: =IF(AND(ISNUMBER(N27),ISNUMBER(O27),ISNUMBER(P27),ISNUMBER(Q27),ISNUMBER(R27),ISNUMBER(S27),ISNUMBER(T27),ISNUMBER(U27),N27>0,O27>0),U27-T27,"") -> 2.1321 | Y27: =IF(AND(ISNUMBER(N27),ISNUMBER(O27),ISNUMBER(P27),ISNUMBER(Q27),ISNUMBER(R27),ISNUMBER(S27),ISNUMBER(T27),ISNUMBER(U27),N27>0,O27>0),Q27-P27,"") -> 0.0339 | Z27: =IF(AND(ISNUMBER(N27),ISNUMBER(O27),ISNUMBER(P27),ISNUMBER(Q27),ISNUMBER(R27),ISNUMBER(S27),ISNUMBER(T27),ISNUMBER(U27),N27>0,O27>0),MIN((INT(N27)*3+ROUND(MOD(N27,1)*10,0))/3,(INT(O27)*3+ROUND(MOD(O27,1)*10,0))/3),"") -> 3 | AA27: =IF(ISNUMBER(Z27),W27*Z27,"") -> 18.6924 | AB27: =IF(ISNUMBER(Z27),X27*Z27,"") -> 6.3963 | AC27: =IF(ISNUMBER(Z27),Y27*Z27,"") -> 0.1017
A28: Jeffrey Springs | B28: 30 | C28: TB | D28: P | E28: L | F28: United States | G28: 2023 | H28: 45047 | I28: 45503 | J28: 92 | K28: 68 | L28: 25 | M28: 66 | N28: 200.1 | O28: 346.2 | P28: 0.2213 | Q28: 0.1111 | R28: 3.1448 | S28: 4.8808 | T28: 3.4136 | U28: 5.15 | V28: 17677 | W28: =IF(AND(ISNUMBER(N28),ISNUMBER(O28),ISNUMBER(P28),ISNUMBER(Q28),ISNUMBER(R28),ISNUMBER(S28),ISNUMBER(T28),ISNUMBER(U28),N28>0,O28>0),S28-R28,"") -> 1.736 | X28: =IF(AND(ISNUMBER(N28),ISNUMBER(O28),ISNUMBER(P28),ISNUMBER(Q28),ISNUMBER(R28),ISNUMBER(S28),ISNUMBER(T28),ISNUMBER(U28),N28>0,O28>0),U28-T28,"") -> 1.7364 | Y28: =IF(AND(ISNUMBER(N28),ISNUMBER(O28),ISNUMBER(P28),ISNUMBER(Q28),ISNUMBER(R28),ISNUMBER(S28),ISNUMBER(T28),ISNUMBER(U28),N28>0,O28>0),Q28-P28,"") -> -0.1102 | Z28: =IF(AND(ISNUMBER(N28),ISNUMBER(O28),ISNUMBER(P28),ISNUMBER(Q28),ISNUMBER(R28),ISNUMBER(S28),ISNUMBER(T28),ISNUMBER(U28),N28>0,O28>0),MIN((INT(N28)*3+ROUND(MOD(N28,1)*10,0))/3,(INT(O28)*3+ROUND(MOD(O28,1)*10,0))/3),"") -> 200.33333 | AA28: =IF(ISNUMBER(Z28),W28*Z28,"") -> 347.77867 | AB28: =IF(ISNUMBER(Z28),X28*Z28,"") -> 347.8588 | AC28: =IF(ISNUMBER(Z28),Y28*Z28,"") -> -22.076733
A29: Kris Bubic | B29: 25 | C29: KC | D29: P | E29: L | F29: United States | G29: 2023 | H29: 45044 | I29: 45480 | J29: 67 | K29: 61 | L29: 57 | M29: 29 | N29: 309 | O29: 201.2 | P29: 0.0945 | Q29: 0.1713 | R29: 4.8932 | S29: 2.9008 | T29: 4.9266 | U29: 2.9259 | V29: 21455 | W29: =IF(AND(ISNUMBER(N29),ISNUMBER(O29),ISNUMBER(P29),ISNUMBER(Q29),ISNUMBER(R29),ISNUMBER(S29),ISNUMBER(T29),ISNUMBER(U29),N29>0,O29>0),S29-R29,"") -> -1.9924 | X29: =IF(AND(ISNUMBER(N29),ISNUMBER(O29),ISNUMBER(P29),ISNUMBER(Q29),ISNUMBER(R29),ISNUMBER(S29),ISNUMBER(T29),ISNUMBER(U29),N29>0,O29>0),U29-T29,"") -> -2.0007 | Y29: =IF(AND(ISNUMBER(N29),ISNUMBER(O29),ISNUMBER(P29),ISNUMBER(Q29),ISNUMBER(R29),ISNUMBER(S29),ISNUMBER(T29),ISNUMBER(U29),N29>0,O29>0),Q29-P29,"") -> 0.0768 | Z29: =IF(AND(ISNUMBER(N29),ISNUMBER(O29),ISNUMBER(P29),ISNUMBER(Q29),ISNUMBER(R29),ISNUMBER(S29),ISNUMBER(T29),ISNUMBER(U29),N29>0,O29>0),MIN((INT(N29)*3+ROUND(MOD(N29,1)*10,0))/3,(INT(O29)*3+ROUND(MOD(O29,1)*10,0))/3),"") -> 201.66667 | AA29: =IF(ISNUMBER(Z29),W29*Z29,"") -> -401.80067 | AB29: =IF(ISNUMBER(Z29),X29*Z29,"") -> -403.4745 | AC29: =IF(ISNUMBER(Z29),Y29*Z29,"") -> 15.488
A30: JT Brubaker | B30: 29 | C30: PIT | D30: P | E30: R | F30: United States | G30: 2023 | H30: 45028 | I30: 45829 | J30: 63 | K30: 58 | L30: 61 | M30: 2 | N30: 315.2 | O30: 89 | P30: 0.1548 | Q30: 0.0627 | R30: 4.9894 | S30: 3.6404 | T30: 4.4324 | U30: 3.8548 | V30: 17578 | W30: =IF(AND(ISNUMBER(N30),ISNUMBER(O30),ISNUMBER(P30),ISNUMBER(Q30),ISNUMBER(R30),ISNUMBER(S30),ISNUMBER(T30),ISNUMBER(U30),N30>0,O30>0),S30-R30,"") -> -1.349 | X30: =IF(AND(ISNUMBER(N30),ISNUMBER(O30),ISNUMBER(P30),ISNUMBER(Q30),ISNUMBER(R30),ISNUMBER(S30),ISNUMBER(T30),ISNUMBER(U30),N30>0,O30>0),U30-T30,"") -> -0.5776 | Y30: =IF(AND(ISNUMBER(N30),ISNUMBER(O30),ISNUMBER(P30),ISNUMBER(Q30),ISNUMBER(R30),ISNUMBER(S30),ISNUMBER(T30),ISNUMBER(U30),N30>0,O30>0),Q30-P30,"") -> -0.0921 | Z30: =IF(AND(ISNUMBER(N30),ISNUMBER(O30),ISNUMBER(P30),ISNUMBER(Q30),ISNUMBER(R30),ISNUMBER(S30),ISNUMBER(T30),ISNUMBER(U30),N30>0,O30>0),MIN((INT(N30)*3+ROUND(MOD(N30,1)*10,0))/3,(INT(O30)*3+ROUND(MOD(O30,1)*10,0))/3),"") -> 89 | AA30: =IF(ISNUMBER(Z30),W30*Z30,"") -> -120.061 | AB30: =IF(ISNUMBER(Z30),X30*Z30,"") -> -51.4064 | AC30: =IF(ISNUMBER(Z30),Y30*Z30,"") -> -8.1969
A31: Cade Cavalli | B31: 24 | C31: WAS | D31: P | E31: R | F31: United States | G31: 2023 | H31: 45007 | I31: 45875 | J31: 1 | K31: 42 | L31: 1 | M31: 42 | N31: 4.1 | O31: 218.1 | P31: 0.1739 | Q31: 0.1914 | R31: 14.5385 | S31: 3.2977 | T31: 3.8 | U31: 3.5353 | V31: 27473 | W31: =IF(AND(ISNUMBER(N31),ISNUMBER(O31),ISNUMBER(P31),ISNUMBER(Q31),ISNUMBER(R31),ISNUMBER(S31),ISNUMBER(T31),ISNUMBER(U31),N31>0,O31>0),S31-R31,"") -> -11.2408 | X31: =IF(AND(ISNUMBER(N31),ISNUMBER(O31),ISNUMBER(P31),ISNUMBER(Q31),ISNUMBER(R31),ISNUMBER(S31),ISNUMBER(T31),ISNUMBER(U31),N31>0,O31>0),U31-T31,"") -> -0.2647 | Y31: =IF(AND(ISNUMBER(N31),ISNUMBER(O31),ISNUMBER(P31),ISNUMBER(Q31),ISNUMBER(R31),ISNUMBER(S31),ISNUMBER(T31),ISNUMBER(U31),N31>0,O31>0),Q31-P31,"") -> 0.0175 | Z31: =IF(AND(ISNUMBER(N31),ISNUMBER(O31),ISNUMBER(P31),ISNUMBER(Q31),ISNUMBER(R31),ISNUMBER(S31),ISNUMBER(T31),ISNUMBER(U31),N31>0,O31>0),MIN((INT(N31)*3+ROUND(MOD(N31,1)*10,0))/3,(INT(O31)*3+ROUND(MOD(O31,1)*10,0))/3),"") -> 4.3333333 | AA31: =IF(ISNUMBER(Z31),W31*Z31,"") -> -48.710133 | AB31: =IF(ISNUMBER(Z31),X31*Z31,"") -> -1.1470333 | AC31: =IF(ISNUMBER(Z31),Y31*Z31,"") -> 0.075833333
A32: Lucas Gilbreath | B32: 27 | C32: COL | D32: P | E32: L | F32: United States | G32: 2023 | H32: 44999 | I32: 45520 | J32: 94 | K32: 4 | L32: 1 | M32: 0 | N32: 85.2 | O32: 2 | P32: 0.1183 | Q32: 0.0625 | R32: 3.7821 | S32: 31.5 | T32: 3.9235 | U32: 17.155 | V32: 21290 | W32: =IF(AND(ISNUMBER(N32),ISNUMBER(O32),ISNUMBER(P32),ISNUMBER(Q32),ISNUMBER(R32),ISNUMBER(S32),ISNUMBER(T32),ISNUMBER(U32),N32>0,O32>0),S32-R32,"") -> 27.7179 | X32: =IF(AND(ISNUMBER(N32),ISNUMBER(O32),ISNUMBER(P32),ISNUMBER(Q32),ISNUMBER(R32),ISNUMBER(S32),ISNUMBER(T32),ISNUMBER(U32),N32>0,O32>0),U32-T32,"") -> 13.2315 | Y32: =IF(AND(ISNUMBER(N32),ISNUMBER(O32),ISNUMBER(P32),ISNUMBER(Q32),ISNUMBER(R32),ISNUMBER(S32),ISNUMBER(T32),ISNUMBER(U32),N32>0,O32>0),Q32-P32,"") -> -0.0558 | Z32: =IF(AND(ISNUMBER(N32),ISNUMBER(O32),ISNUMBER(P32),ISNUMBER(Q32),ISNUMBER(R32),ISNUMBER(S32),ISNUMBER(T32),ISNUMBER(U32),N32>0,O32>0),MIN((INT(N32)*3+ROUND(MOD(N32,1)*10,0))/3,(INT(O32)*3+ROUND(MOD(O32,1)*10,0))/3),"") -> 2 | AA32: =IF(ISNUMBER(Z32),W32*Z32,"") -> 55.4358 | AB32: =IF(ISNUMBER(Z32),X32*Z32,"") -> 26.463 | AC32: =IF(ISNUMBER(Z32),Y32*Z32,"") -> -0.1116
A33: Scott Effross | B33: 28 | C33: NYY | D33: P | E33: R | F33: United States | G33: 2022 | H33: 44847 | I33: 45536 | J33: 14 | K33: 14 | L33: 0 | M33: 0 | N33: 14.2 | O33: 14 | P33: 0.2931 | Q33: 0.0462 | R33: 3.6818 | S33: 7.7143 | T33: 3.31 | U33: 4.9271 | V33: 18384 | W33: =IF(AND(ISNUMBER(N33),ISNUMBER(O33),ISNUMBER(P33),ISNUMBER(Q33),ISNUMBER(R33),ISNUMBER(S33),ISNUMBER(T33),ISNUMBER(U33),N33>0,O33>0),S33-R33,"") -> 4.0325 | X33: =IF(AND(ISNUMBER(N33),ISNUMBER(O33),ISNUMBER(P33),ISNUMBER(Q33),ISNUMBER(R33),ISNUMBER(S33),ISNUMBER(T33),ISNUMBER(U33),N33>0,O33>0),U33-T33,"") -> 1.6171 | Y33: =IF(AND(ISNUMBER(N33),ISNUMBER(O33),ISNUMBER(P33),ISNUMBER(Q33),ISNUMBER(R33),ISNUMBER(S33),ISNUMBER(T33),ISNUMBER(U33),N33>0,O33>0),Q33-P33,"") -> -0.2469 | Z33: =IF(AND(ISNUMBER(N33),ISNUMBER(O33),ISNUMBER(P33),ISNUMBER(Q33),ISNUMBER(R33),ISNUMBER(S33),ISNUMBER(T33),ISNUMBER(U33),N33>0,O33>0),MIN((INT(N33)*3+ROUND(MOD(N33,1)*10,0))/3,(INT(O33)*3+ROUND(MOD(O33,1)*10,0))/3),"") -> 14 | AA33: =IF(ISNUMBER(Z33),W33*Z33,"") -> 56.455 | AB33: =IF(ISNUMBER(Z33),X33*Z33,"") -> 22.6394 | AC33: =IF(ISNUMBER(Z33),Y33*Z33,"") -> -3.4566
... A40: Cody Poteet | B40: 27 | C40: MIA | D40: P | E40: R | F40: United States | G40: 2022 | H40: 44790 | I40: 45395 | J40: 7 | K40: 6 | L40: 7 | M40: 4 | N40: 30.2 | O40: 27 | P40: 0.1212 | Q40: 0.0625 | R40: 4.9891 | S40: 3.6667 | T40: 5.62 | U40: 4.0902 | V40: 18769 | W40: =IF(AND(ISNUMBER(N40),ISNUMBER(O40),ISNUMBER(P40),ISNUMBER(Q40),ISNUMBER(R40),ISNUMBER(S40),ISNUMBER(T40),ISNUMBER(U40),N40>0,O40>0),S40-R40,"") -> -1.3224 | X40: =IF(AND(ISNUMBER(N40),ISNUMBER(O40),ISNUMBER(P40),ISNUMBER(Q40),ISNUMBER(R40),ISNUMBER(S40),ISNUMBER(T40),ISNUMBER(U40),N40>0,O40>0),U40-T40,"") -> -1.5298 | Y40: =IF(AND(ISNUMBER(N40),ISNUMBER(O40),ISNUMBER(P40),ISNUMBER(Q40),ISNUMBER(R40),ISNUMBER(S40),ISNUMBER(T40),ISNUMBER(U40),N40>0,O40>0),Q40-P40,"") -> -0.0587 | Z40: =IF(AND(ISNUMBER(N40),ISNUMBER(O40),ISNUMBER(P40),ISNUMBER(Q40),ISNUMBER(R40),ISNUMBER(S40),ISNUMBER(T40),ISNUMBER(U40),N40>0,O40>0),MIN((INT(N40)*3+ROUND(MOD(N40,1)*10,0))/3,(INT(O40)*3+ROUND(MOD(O40,1)*10,0))/3),"") -> 27 | AA40: =IF(ISNUMBER(Z40),W40*Z40,"") -> -35.7048 | AB40: =IF(ISNUMBER(Z40),X40*Z40,"") -> -41.3046 | AC40: =IF(ISNUMBER(Z40),Y40*Z40,"") -> -1.5849
A41: Max Meyer | B41: 23 | C41: MIA | D41: P | E41: R | F41: United States | G41: 2022 | H41: 44782 | I41: 45383 | K41: 23 | M41: 23 | O41: 121.2 | Q41: 0.1407 | S41: 5.1781 | U41: 5.1346 | V41: 27474 | W41: =IF(AND(ISNUMBER(N41),ISNUMBER(O41),ISNUMBER(P41),ISNUMBER(Q41),ISNUMBER(R41),ISNUMBER(S41),ISNUMBER(T41),ISNUMBER(U41),N41>0,O41>0),S41-R41,"") | X41: =IF(AND(ISNUMBER(N41),ISNUMBER(O41),ISNUMBER(P41),ISNUMBER(Q41),ISNUMBER(R41),ISNUMBER(S41),ISNUMBER(T41),ISNUMBER(U41),N41>0,O41>0),U41-T41,"") | Y41: =IF(AND(ISNUMBER(N41),ISNUMBER(O41),ISNUMBER(P41),ISNUMBER(Q41),ISNUMBER(R41),ISNUMBER(S41),ISNUMBER(T41),ISNUMBER(U41),N41>0,O41>0),Q41-P41,"") | Z41: =IF(AND(ISNUMBER(N41),ISNUMBER(O41),ISNUMBER(P41),ISNUMBER(Q41),ISNUMBER(R41),ISNUMBER(S41),ISNUMBER(T41),ISNUMBER(U41),N41>0,O41>0),MIN((INT(N41)*3+ROUND(MOD(N41,1)*10,0))/3,(INT(O41)*3+ROUND(MOD(O41,1)*10,0))/3),"") | AA41: =IF(ISNUMBER(Z41),W41*Z41,"") | AB41: =IF(ISNUMBER(Z41),X41*Z41,"") | AC41: =IF(ISNUMBER(Z41),Y41*Z41,"")
A42: Humberto Castellanos | B42: 24 | C42: ARI | D42: P | E42: R | F42: Mexico | G42: 2022 | H42: 44781 | I42: 45450 | J42: 22 | K42: 7 | L42: 7 | M42: 0 | N42: 56.1 | O42: 10.1 | P42: 0.085 | Q42: 0.0625 | R42: 5.2722 | S42: 5.2258 | T42: 5.0744 | U42: 3.55 | V42: 21183 | W42: =IF(AND(ISNUMBER(N42),ISNUMBER(O42),ISNUMBER(P42),ISNUMBER(Q42),ISNUMBER(R42),ISNUMBER(S42),ISNUMBER(T42),ISNUMBER(U42),N42>0,O42>0),S42-R42,"") -> -0.0464 | X42: =IF(AND(ISNUMBER(N42),ISNUMBER(O42),ISNUMBER(P42),ISNUMBER(Q42),ISNUMBER(R42),ISNUMBER(S42),ISNUMBER(T42),ISNUMBER(U42),N42>0,O42>0),U42-T42,"") -> -1.5244 | Y42: =IF(AND(ISNUMBER(N42),ISNUMBER(O42),ISNUMBER(P42),ISNUMBER(Q42),ISNUMBER(R42),ISNUMBER(S42),ISNUMBER(T42),ISNUMBER(U42),N42>0,O42>0),Q42-P42,"") -> -0.0225 | Z42: =IF(AND(ISNUMBER(N42),ISNUMBER(O42),ISNUMBER(P42),ISNUMBER(Q42),ISNUMBER(R42),ISNUMBER(S42),ISNUMBER(T42),ISNUMBER(U42),N42>0,O42>0),MIN((INT(N42)*3+ROUND(MOD(N42,1)*10,0))/3,(INT(O42)*3+ROUND(MOD(O42,1)*10,0))/3),"") -> 10.333333 | AA42: =IF(ISNUMBER(Z42),W42*Z42,"") -> -0.47946667 | AB42: =IF(ISNUMBER(Z42),X42*Z42,"") -> -15.752133 | AC42: =IF(ISNUMBER(Z42),Y42*Z42,"") -> -0.2325
A43: Tanner Rainey | B43: 29 | C43: WAS | D43: P | E43: R | F43: United States | G43: 2022 | H43: 44776 | I43: 45199 | J43: 110 | K43: 64 | L43: 0 | M43: 0 | N43: 100.1 | O43: 61.2 | P43: 0.1773 | Q43: 0.0601 | R43: 4.7542 | S43: 5.6919 | T43: 4.6481 | U43: 5.1723 | V43: 17610 | W43: =IF(AND(ISNUMBER(N43),ISNUMBER(O43),ISNUMBER(P43),ISNUMBER(Q43),ISNUMBER(R43),ISNUMBER(S43),ISNUMBER(T43),ISNUMBER(U43),N43>0,O43>0),S43-R43,"") -> 0.9377 | X43: =IF(AND(ISNUMBER(N43),ISNUMBER(O43),ISNUMBER(P43),ISNUMBER(Q43),ISNUMBER(R43),ISNUMBER(S43),ISNUMBER(T43),ISNUMBER(U43),N43>0,O43>0),U43-T43,"") -> 0.5242 | Y43: =IF(AND(ISNUMBER(N43),ISNUMBER(O43),ISNUMBER(P43),ISNUMBER(Q43),ISNUMBER(R43),ISNUMBER(S43),ISNUMBER(T43),ISNUMBER(U43),N43>0,O43>0),Q43-P43,"") -> -0.1172 | Z43: =IF(AND(ISNUMBER(N43),ISNUMBER(O43),ISNUMBER(P43),ISNUMBER(Q43),ISNUMBER(R43),ISNUMBER(S43),ISNUMBER(T43),ISNUMBER(U43),N43>0,O43>0),MIN((INT(N43)*3+ROUND(MOD(N43,1)*10,0))/3,(INT(O43)*3+ROUND(MOD(O43,1)*10,0))/3),"") -> 61.666667 | AA43: =IF(ISNUMBER(Z43),W43*Z43,"") -> 57.824833 | AB43: =IF(ISNUMBER(Z43),X43*Z43,"") -> 32.325667 | AC43: =IF(ISNUMBER(Z43),Y43*Z43,"") -> -7.2273333
A44: Brad Wieck | B44: 30 | C44: CHC | D44: P | E44: L | F44: United States | G44: 2022 | H44: 44762 | J44: 60 | K44: NULL | L44: 0 | M44: NULL | N44: 52.2 | O44: NULL | P44: 0.2455 | Q44: NULL | R44: 4.1013 | S44: NULL | T44: 3.9575 | U44: NULL | V44: 16390 | W44: =IF(AND(ISNUMBER(N44),ISNUMBER(O44),ISNUMBER(P44),ISNUMBER(Q44),ISNUMBER(R44),ISNUMBER(S44),ISNUMBER(T44),ISNUMBER(U44),N44>0,O44>0),S44-R44,"") | X44: =IF(AND(ISNUMBER(N44),ISNUMBER(O44),ISNUMBER(P44),ISNUMBER(Q44),ISNUMBER(R44),ISNUMBER(S44),ISNUMBER(T44),ISNUMBER(U44),N44>0,O44>0),U44-T44,"") | Y44: =IF(AND(ISNUMBER(N44),ISNUMBER(O44),ISNUMBER(P44),ISNUMBER(Q44),ISNUMBER(R44),ISNUMBER(S44),ISNUMBER(T44),ISNUMBER(U44),N44>0,O44>0),Q44-P44,"") | Z44: =IF(AND(ISNUMBER(N44),ISNUMBER(O44),ISNUMBER(P44),ISNUMBER(Q44),ISNUMBER(R44),ISNUMBER(S44),ISNUMBER(T44),ISNUMBER(U44),N44>0,O44>0),MIN((INT(N44)*3+ROUND(MOD(N44,1)*10,0))/3,(INT(O44)*3+ROUND(MOD(O44,1)*10,0))/3),"") | AA44: =IF(ISNUMBER(Z44),W44*Z44,"") | AB44: =IF(ISNUMBER(Z44),X44*Z44,"") | AC44: =IF(ISNUMBER(Z44),Y44*Z44,"")
A45: Vladimir Gutierrez | B45: 26 | C45: CIN | D45: P | E45: R | F45: Cuba | G45: 2022 | H45: 44762 | I45: 45382 | J45: 22 | K45: 1 | L45: 22 | M45: 0 | N45: 114 | O45: 4 | P45: 0.0847 | Q45: 0.1176 | R45: 4.7368 | S45: 6.75 | T45: 5.22 | U45: 5.92 | V45: 19278 | W45: =IF(AND(ISNUMBER(N45),ISNUMBER(O45),ISNUMBER(P45),ISNUMBER(Q45),ISNUMBER(R45),ISNUMBER(S45),ISNUMBER(T45),ISNUMBER(U45),N45>0,O45>0),S45-R45,"") -> 2.0132 | X45: =IF(AND(ISNUMBER(N45),ISNUMBER(O45),ISNUMBER(P45),ISNUMBER(Q45),ISNUMBER(R45),ISNUMBER(S45),ISNUMBER(T45),ISNUMBER(U45),N45>0,O45>0),U45-T45,"") -> 0.7 | Y45: =IF(AND(ISNUMBER(N45),ISNUMBER(O45),ISNUMBER(P45),ISNUMBER(Q45),ISNUMBER(R45),ISNUMBER(S45),ISNUMBER(T45),ISNUMBER(U45),N45>0,O45>0),Q45-P45,"") -> 0.0329 | Z45: =IF(AND(ISNUMBER(N45),ISNUMBER(O45),ISNUMBER(P45),ISNUMBER(Q45),ISNUMBER(R45),ISNUMBER(S45),ISNUMBER(T45),ISNUMBER(U45),N45>0,O45>0),MIN((INT(N45)*3+ROUND(MOD(N45,1)*10,0))/3,(INT(O45)*3+ROUND(MOD(O45,1)*10,0))/3),"") -> 4 | AA45: =IF(ISNUMBER(Z45),W45*Z45,"") -> 8.0528 | AB45: =IF(ISNUMBER(Z45),X45*Z45,"") -> 2.8 | AC45: =IF(ISNUMBER(Z45),Y45*Z45,"") -> 0.1316
A46: Andrew Kittredge | B46: 32 | C46: TB | D46: P | E46: R | F46: United States | G46: 2022 | H46: 44734 | I46: 45156 | J46: 102 | K46: 142 | L46: 12 | M46: 0 | N46: 129.1 | O46: 135.1 | P46: 0.2084 | Q46: 0.1982 | R46: 2.7835 | S46: 3.0591 | T46: 3.249 | U46: 3.5618 | V46: 12828 | W46: =IF(AND(ISNUMBER(N46),ISNUMBER(O46),ISNUMBER(P46),ISNUMBER(Q46),ISNUMBER(R46),ISNUMBER(S46),ISNUMBER(T46),ISNUMBER(U46),N46>0,O46>0),S46-R46,"") -> 0.2756 | X46: =IF(AND(ISNUMBER(N46),ISNUMBER(O46),ISNUMBER(P46),ISNUMBER(Q46),ISNUMBER(R46),ISNUMBER(S46),ISNUMBER(T46),ISNUMBER(U46),N46>0,O46>0),U46-T46,"") -> 0.3128 | Y46: =IF(AND(ISNUMBER(N46),ISNUMBER(O46),ISNUMBER(P46),ISNUMBER(Q46),ISNUMBER(R46),ISNUMBER(S46),ISNUMBER(T46),ISNUMBER(U46),N46>0,O46>0),Q46-P46,"") -> -0.0102 | Z46: =IF(AND(ISNUMBER(N46),ISNUMBER(O46),ISNUMBER(P46),ISNUMBER(Q46),ISNUMBER(R46),ISNUMBER(S46),ISNUMBER(T46),ISNUMBER(U46),N46>0,O46>0),MIN((INT(N46)*3+ROUND(MOD(N46,1)*10,0))/3,(INT(O46)*3+ROUND(MOD(O46,1)*10,0))/3),"") -> 129.33333 | AA46: =IF(ISNUMBER(Z46),W46*Z46,"") -> 35.644267 | AB46: =IF(ISNUMBER(Z46),X46*Z46,"") -> 40.455467 | AC46: =IF(ISNUMBER(Z46),Y46*Z46,"") -> -1.3192
...

Sheet Unmatched - Check Manually
A1: Row | B1: Player | C1: Period | D1: Issue
A2: 11 | B2: Reiss Knehr | C2: After | D2: No seasons found for [2024, 2025, 2026]
A3: 19 | B3: Connor Overton | C3: After | D3: No seasons found for [2024, 2025, 2026]
A4: 21 | B4: Luis Garcia | C4: ID | D4: Ambiguous name, candidates: ['garcilu03', 'garcilu05']
A5: 41 | B5: Max Meyer | C5: Before | D5: No seasons found for [2019, 2020, 2021]
A6: 44 | B6: Brad Wieck | C6: After | D6: No seasons found for [2023, 2024, 2025]
A7: 47 | B7: Hyun-Jin Ryu | C7: ID | D7: No name match in any CSV
A8: 55 | B8: Deolis Guerra | C8: After | D8: No seasons found for [2023, 2024, 2025]
A9: 59 | B9: Evan Marshall | C9: After | D9: No seasons found for [2022, 2023, 2024]
A10: 63 | B10: John Axford | C10: After | D10: No seasons found for [2022, 2023, 2024]
A11: 66 | B11: Jimmy Nelson | C11: After | D11: No seasons found for [2022, 2023, 2024]
A12: 72 | B12: Keone Kela | C12: After | D12: No seasons found for [2022, 2023, 2024]
A13: 75 | B13: Ljay Newsome | C13: After | D13: No seasons found for [2022, 2023, 2024]
... A34: 150 | B34: Blake Wood | C34: After | D34: No seasons found for [2019, 2020, 2021]

Sheet Innings-Weighted Summary
A1: Statistic | B1: Unweighted Average Change | C1: Innings-Weighted Average Change | D1: Interpretation
A2: ERA | B2: =AVERAGE('MLB Pitchers 2018-2023 TJ'!W2:W160) -> 0.66392835 | C2: =SUM('MLB Pitchers 2018-2023 TJ'!AA2:AA160)/SUM('MLB Pitchers 2018-2023 TJ'!Z2:Z160) -> 0.31907945 | D2: Negative means improvement
A3: FIP | B3: =AVERAGE('MLB Pitchers 2018-2023 TJ'!X2:X160) -> 0.5400252 | C3: =SUM('MLB Pitchers 2018-2023 TJ'!AB2:AB160)/SUM('MLB Pitchers 2018-2023 TJ'!Z2:Z160) -> 0.37415863 | D3: Negative means improvement
A4: K-BB% | B4: =AVERAGE('MLB Pitchers 2018-2023 TJ'!Y2:Y160) -> -0.030917323 | C4: =SUM('MLB Pitchers 2018-2023 TJ'!AC2:AC160)/SUM('MLB Pitchers 2018-2023 TJ'!Z2:Z160) -> -0.032949471 | D4: Positive means improvement
A6: Method | B6: Weight = minimum of pre- and post-surgery innings pitched
A7: Eligibility | B7: Only pitchers with valid before/after IP, ERA, FIP, and K-BB%
A8: Baseball innings | B8: 65.2 is converted to 65 + 2/3 innings
A9: Direction | B9: After surgery minus before surgery
A11: Eligible paired pitchers | B11: =COUNT('MLB Pitchers 2018-2023 TJ'!Z2:Z160) -> 127
